生原因:
Traceback (most recent call last):
  File "/home/ubuntu/group_1_work/technical_assistant/error_check_file_03.py", line 4, in <module>
    print(personal["mame"])
          ~~~~~~~~^^^^^^^^

生エラー:
KeyError: 'mame'

要約原因:
"personal" という辞書からキー "mame" の値を取得しようとしたが、そのキーが存在しなかったことが原因です。

要約エラー:
キーのエラーです。

解決策:
存在するキーを指定してください。
