生原因:
Traceback (most recent call last):
  File "/home/ubuntu/group_1_work/technical_assistant/error_check_file_02.py", line 4, in <module>
    li[6]
    ~~^^^

生エラー:
IndexError: list index out of range

要約原因:
リスト "li" のインデックス 6 にアクセスしようとしたが、そのインデックスが存在しなかったことが原因です。

要約エラー:
リストの範囲外のインデックスにアクセスしようとしたことを示しています。

解決策:
リストのインデックスが範囲外にならないようにします。
