Traceback (most recent call last):
  File "/home/ubuntu/group_1_work/technical_assistant/error_check_file_03.py", line 4, in <module>
    print(personal["mame"])
          ~~~~~~~~^^^^^^^^
KeyError: 'mame'
