生原因:
Traceback (most recent call last):
  File "/home/ubuntu/group_1_work/technical_assistant/error_check_file_05.py", line 3, in <module>
    with open("nonexistent_file.txt", "r") as f:
         ^^^^^^^^^^^^^^^^^^^^^^^^^^^^^^^^^

生エラー:
FileNotFoundError: [Errno 2] No such file or directory: 'nonexistent_file.txt'

要約原因:
 "nonexistent_file.txt" という名前のファイルを読み込もうと試みましたが、そのファイルが存在しない事が原因です。

 要約エラー:
 ファイルが存在しません。

 解決策:
 ファイルの存在やファイルのパスを確認して下さい。

 